refcode测试失败，BigCodeBench/647的依赖{'datetime': '5.5', 'dateutil': '2.9.0.post0', 'python': '3.12', 'pytz': '2024.1'}需要适配
错误信息:
Command '['/datanfs2/chenrongyi/conda_env/datetime5.5_dateutil2.9.0.post0_python3.12_pytz2024.1/bin/python', '-m', 'unittest', 'test_2_0.py']' returned non-zero exit status 1.
stderr:
Traceback (most recent call last):
  File "<frozen runpy>", line 198, in _run_module_as_main
  File "<frozen runpy>", line 88, in _run_code
  File "/datanfs2/chenrongyi/conda_env/datetime5.5_dateutil2.9.0.post0_python3.12_pytz2024.1/lib/python3.12/unittest/__main__.py", line 18, in <module>
    main(module=None)
  File "/datanfs2/chenrongyi/conda_env/datetime5.5_dateutil2.9.0.post0_python3.12_pytz2024.1/lib/python3.12/unittest/main.py", line 104, in __init__
    self.parseArgs(argv)
  File "/datanfs2/chenrongyi/conda_env/datetime5.5_dateutil2.9.0.post0_python3.12_pytz2024.1/lib/python3.12/unittest/main.py", line 153, in parseArgs
    self.createTests()
  File "/datanfs2/chenrongyi/conda_env/datetime5.5_dateutil2.9.0.post0_python3.12_pytz2024.1/lib/python3.12/unittest/main.py", line 164, in createTests
    self.test = self.testLoader.loadTestsFromNames(self.testNames,
                ^^^^^^^^^^^^^^^^^^^^^^^^^^^^^^^^^^^^^^^^^^^^^^^^^^
  File "/datanfs2/chenrongyi/conda_env/datetime5.5_dateutil2.9.0.post0_python3.12_pytz2024.1/lib/python3.12/unittest/loader.py", line 207, in loadTestsFromNames
    suites = [self.loadTestsFromName(name, module) for name in names]
              ^^^^^^^^^^^^^^^^^^^^^^^^^^^^^^^^^^^^
  File "/datanfs2/chenrongyi/conda_env/datetime5.5_dateutil2.9.0.post0_python3.12_pytz2024.1/lib/python3.12/unittest/loader.py", line 137, in loadTestsFromName
    module = __import__(module_name)
             ^^^^^^^^^^^^^^^^^^^^^^^
  File "/home/chenrongyi/codes/VersiBCB_Benchmark/test_2_0.py", line 11
    </end>
    ^
SyntaxError: invalid syntax

stdout:

Traceback:
 Traceback (most recent call last):
  File "/home/chenrongyi/codes/VersiBCB_Benchmark/utils/testPassBCB.py", line 92, in passTaskTest
    result = run_tests_in_virtualenv(venv_dir, test_file_path,outputTestInfo=outputTestInfo)
  File "/home/chenrongyi/codes/VersiBCB_Benchmark/utils/testPassBCB.py", line 33, in run_tests_in_virtualenv
    raise subprocess.CalledProcessError(
subprocess.CalledProcessError: Command '['/datanfs2/chenrongyi/conda_env/datetime5.5_dateutil2.9.0.post0_python3.12_pytz2024.1/bin/python', '-m', 'unittest', 'test_2_0.py']' returned non-zero exit status 1.

refcode测试失败，BigCodeBench/647的依赖{'datetime': '5.5', 'dateutil': '2.9.0.post0', 'python': '3.12', 'pytz': '2024.1'}需要适配
错误信息:
Command '['/datanfs2/chenrongyi/conda_env/datetime5.5_dateutil2.9.0.post0_python3.12_pytz2024.1/bin/python', '-m', 'unittest', 'test_2_0.py']' returned non-zero exit status 1.
stderr:
EEEEF
======================================================================
ERROR: test_case_1 (test_2_0.TestCases.test_case_1)
----------------------------------------------------------------------
Traceback (most recent call last):
  File "/home/chenrongyi/codes/VersiBCB_Benchmark/test_2_0.py", line 26, in test_case_1
    result = task_func('2022-01-01 11:59:59', 'UTC', 'America/Chicago')
             ^^^^^^^^^
NameError: name 'task_func' is not defined

======================================================================
ERROR: test_case_2 (test_2_0.TestCases.test_case_2)
----------------------------------------------------------------------
Traceback (most recent call last):
  File "/home/chenrongyi/codes/VersiBCB_Benchmark/test_2_0.py", line 32, in test_case_2
    result = task_func('2022-01-01 11:59:59', 'America/New_York', 'Asia/Kolkata')
             ^^^^^^^^^
NameError: name 'task_func' is not defined

======================================================================
ERROR: test_case_4 (test_2_0.TestCases.test_case_4)
----------------------------------------------------------------------
Traceback (most recent call last):
  File "/home/chenrongyi/codes/VersiBCB_Benchmark/test_2_0.py", line 50, in test_case_4
    result = task_func(future_date, 'UTC', 'America/Chicago')
             ^^^^^^^^^
NameError: name 'task_func' is not defined

======================================================================
ERROR: test_case_5 (test_2_0.TestCases.test_case_5)
----------------------------------------------------------------------
Traceback (most recent call last):
  File "/home/chenrongyi/codes/VersiBCB_Benchmark/test_2_0.py", line 56, in test_case_5
    result = task_func('2022-01-01 11:59:59', 'Asia/Kolkata', 'America/Los_Angeles')
             ^^^^^^^^^
NameError: name 'task_func' is not defined

======================================================================
FAIL: test_known_time_zone_offset_difference (test_2_0.TestCases.test_known_time_zone_offset_difference)
Test the function with time zones having a known, static offset.
----------------------------------------------------------------------
Traceback (most recent call last):
  File "/home/chenrongyi/codes/VersiBCB_Benchmark/test_2_0.py", line 42, in test_known_time_zone_offset_difference
    result = task_func(known_date_utc, utc_zone, target_zone)
             ^^^^^^^^^
NameError: name 'task_func' is not defined

During handling of the above exception, another exception occurred:

Traceback (most recent call last):
  File "/home/chenrongyi/codes/VersiBCB_Benchmark/test_2_0.py", line 45, in test_known_time_zone_offset_difference
    self.fail(f"task_func raised an exception with known static offset time zones: {e}")
AssertionError: task_func raised an exception with known static offset time zones: name 'task_func' is not defined

----------------------------------------------------------------------
Ran 5 tests in 0.011s

FAILED (failures=1, errors=4)

stdout:

Traceback:
 Traceback (most recent call last):
  File "/home/chenrongyi/codes/VersiBCB_Benchmark/utils/testPassBCB.py", line 92, in passTaskTest
    result = run_tests_in_virtualenv(venv_dir, test_file_path,outputTestInfo=outputTestInfo)
  File "/home/chenrongyi/codes/VersiBCB_Benchmark/utils/testPassBCB.py", line 33, in run_tests_in_virtualenv
    raise subprocess.CalledProcessError(
subprocess.CalledProcessError: Command '['/datanfs2/chenrongyi/conda_env/datetime5.5_dateutil2.9.0.post0_python3.12_pytz2024.1/bin/python', '-m', 'unittest', 'test_2_0.py']' returned non-zero exit status 1.

refcode测试失败，BigCodeBench/647的依赖{'datetime': '5.5', 'dateutil': '2.9.0.post0', 'python': '3.12', 'pytz': '2024.1'}需要适配
错误信息:
Command '['/datanfs2/chenrongyi/conda_env/datetime5.5_dateutil2.9.0.post0_python3.12_pytz2024.1/bin/python', '-m', 'unittest', 'test_2_0.py']' returned non-zero exit status 1.
stderr:
EEEEF
======================================================================
ERROR: test_case_1 (test_2_0.TestCases.test_case_1)
----------------------------------------------------------------------
Traceback (most recent call last):
  File "/home/chenrongyi/codes/VersiBCB_Benchmark/test_2_0.py", line 27, in test_case_1
    result = task_func('2022-01-01 11:59:59', 'UTC', 'America/Chicago')
             ^^^^^^^^^
NameError: name 'task_func' is not defined

======================================================================
ERROR: test_case_2 (test_2_0.TestCases.test_case_2)
----------------------------------------------------------------------
Traceback (most recent call last):
  File "/home/chenrongyi/codes/VersiBCB_Benchmark/test_2_0.py", line 33, in test_case_2
    result = task_func('2022-01-01 11:59:59', 'America/New_York', 'Asia/Kolkata')
             ^^^^^^^^^
NameError: name 'task_func' is not defined

======================================================================
ERROR: test_case_4 (test_2_0.TestCases.test_case_4)
----------------------------------------------------------------------
Traceback (most recent call last):
  File "/home/chenrongyi/codes/VersiBCB_Benchmark/test_2_0.py", line 51, in test_case_4
    result = task_func(future_date, 'UTC', 'America/Chicago')
             ^^^^^^^^^
NameError: name 'task_func' is not defined

======================================================================
ERROR: test_case_5 (test_2_0.TestCases.test_case_5)
----------------------------------------------------------------------
Traceback (most recent call last):
  File "/home/chenrongyi/codes/VersiBCB_Benchmark/test_2_0.py", line 57, in test_case_5
    result = task_func('2022-01-01 11:59:59', 'Asia/Kolkata', 'America/Los_Angeles')
             ^^^^^^^^^
NameError: name 'task_func' is not defined

======================================================================
FAIL: test_known_time_zone_offset_difference (test_2_0.TestCases.test_known_time_zone_offset_difference)
Test the function with time zones having a known, static offset.
----------------------------------------------------------------------
Traceback (most recent call last):
  File "/home/chenrongyi/codes/VersiBCB_Benchmark/test_2_0.py", line 43, in test_known_time_zone_offset_difference
    result = task_func(known_date_utc, utc_zone, target_zone)
             ^^^^^^^^^
NameError: name 'task_func' is not defined

During handling of the above exception, another exception occurred:

Traceback (most recent call last):
  File "/home/chenrongyi/codes/VersiBCB_Benchmark/test_2_0.py", line 46, in test_known_time_zone_offset_difference
    self.fail(f"task_func raised an exception with known static offset time zones: {e}")
AssertionError: task_func raised an exception with known static offset time zones: name 'task_func' is not defined

----------------------------------------------------------------------
Ran 5 tests in 0.011s

FAILED (failures=1, errors=4)

stdout:

Traceback:
 Traceback (most recent call last):
  File "/home/chenrongyi/codes/VersiBCB_Benchmark/utils/testPassBCB.py", line 92, in passTaskTest
    result = run_tests_in_virtualenv(venv_dir, test_file_path,outputTestInfo=outputTestInfo)
  File "/home/chenrongyi/codes/VersiBCB_Benchmark/utils/testPassBCB.py", line 33, in run_tests_in_virtualenv
    raise subprocess.CalledProcessError(
subprocess.CalledProcessError: Command '['/datanfs2/chenrongyi/conda_env/datetime5.5_dateutil2.9.0.post0_python3.12_pytz2024.1/bin/python', '-m', 'unittest', 'test_2_0.py']' returned non-zero exit status 1.

