refcode测试失败，BigCodeBench/484的依赖{'datetime': '5.5', 'numpy': '2.2.1', 'pandas': '2.2.3', 'python': '3.12'}需要适配
错误信息:
Command '['/datanfs2/chenrongyi/conda_env/datetime5.5_numpy2.2.1_pandas2.2.3_python3.12/bin/python', '-m', 'unittest', 'test_1_0.py']' returned non-zero exit status 1.
stderr:
...FFFF.F
======================================================================
FAIL: test_case_4 (test_1_0.TestCases.test_case_4)
----------------------------------------------------------------------
Traceback (most recent call last):
  File "/home/chenrongyi/codes/VersiBCB_Benchmark/test_1_0.py", line 66, in test_case_4
    with self.assertRaises(ValueError):
         ^^^^^^^^^^^^^^^^^^^^^^^^^^^^^
AssertionError: ValueError not raised

======================================================================
FAIL: test_case_5 (test_1_0.TestCases.test_case_5)
----------------------------------------------------------------------
Traceback (most recent call last):
  File "/home/chenrongyi/codes/VersiBCB_Benchmark/test_1_0.py", line 71, in test_case_5
    with self.assertRaises(ValueError):
         ^^^^^^^^^^^^^^^^^^^^^^^^^^^^^
AssertionError: ValueError not raised

======================================================================
FAIL: test_case_6 (test_1_0.TestCases.test_case_6)
----------------------------------------------------------------------
Traceback (most recent call last):
  File "/home/chenrongyi/codes/VersiBCB_Benchmark/test_1_0.py", line 80, in test_case_6
    with self.assertRaises(ValueError):
         ^^^^^^^^^^^^^^^^^^^^^^^^^^^^^
AssertionError: ValueError not raised

======================================================================
FAIL: test_case_7 (test_1_0.TestCases.test_case_7)
----------------------------------------------------------------------
Traceback (most recent call last):
  File "/home/chenrongyi/codes/VersiBCB_Benchmark/test_1_0.py", line 87, in test_case_7
    with self.assertRaises(ValueError):
         ^^^^^^^^^^^^^^^^^^^^^^^^^^^^^
AssertionError: ValueError not raised

======================================================================
FAIL: test_case_9 (test_1_0.TestCases.test_case_9)
----------------------------------------------------------------------
Traceback (most recent call last):
  File "/home/chenrongyi/codes/VersiBCB_Benchmark/test_1_0.py", line 101, in test_case_9
    with self.assertRaises(ValueError):
         ^^^^^^^^^^^^^^^^^^^^^^^^^^^^^
AssertionError: ValueError not raised

----------------------------------------------------------------------
Ran 9 tests in 0.022s

FAILED (failures=5)

stdout:

Traceback:
 Traceback (most recent call last):
  File "/home/chenrongyi/codes/VersiBCB_Benchmark/utils/testPassBCB.py", line 92, in passTaskTest
    result = run_tests_in_virtualenv(venv_dir, test_file_path,outputTestInfo=outputTestInfo)
  File "/home/chenrongyi/codes/VersiBCB_Benchmark/utils/testPassBCB.py", line 33, in run_tests_in_virtualenv
    raise subprocess.CalledProcessError(
subprocess.CalledProcessError: Command '['/datanfs2/chenrongyi/conda_env/datetime5.5_numpy2.2.1_pandas2.2.3_python3.12/bin/python', '-m', 'unittest', 'test_1_0.py']' returned non-zero exit status 1.

refcode测试失败，BigCodeBench/484的依赖{'datetime': '5.5', 'numpy': '2.2.1', 'pandas': '2.2.3', 'python': '3.12'}需要适配
错误信息:
Command '['/datanfs2/chenrongyi/conda_env/datetime5.5_numpy2.2.1_pandas2.2.3_python3.12/bin/python', '-m', 'unittest', 'test_1_0.py']' returned non-zero exit status 1.
stderr:
EEEEEEEEE
======================================================================
ERROR: test_case_1 (test_1_0.TestCases.test_case_1)
----------------------------------------------------------------------
Traceback (most recent call last):
  File "/home/chenrongyi/codes/VersiBCB_Benchmark/test_1_0.py", line 33, in test_case_1
    df = task_func(0, 10000, 100, random_seed=42)
         ^^^^^^^^^
NameError: name 'task_func' is not defined

======================================================================
ERROR: test_case_2 (test_1_0.TestCases.test_case_2)
----------------------------------------------------------------------
Traceback (most recent call last):
  File "/home/chenrongyi/codes/VersiBCB_Benchmark/test_1_0.py", line 47, in test_case_2
    df = task_func(
         ^^^^^^^^^
NameError: name 'task_func' is not defined

======================================================================
ERROR: test_case_3 (test_1_0.TestCases.test_case_3)
----------------------------------------------------------------------
Traceback (most recent call last):
  File "/home/chenrongyi/codes/VersiBCB_Benchmark/test_1_0.py", line 61, in test_case_3
    df = task_func(0, 100, 100, random_seed=42)
         ^^^^^^^^^
NameError: name 'task_func' is not defined

======================================================================
ERROR: test_case_4 (test_1_0.TestCases.test_case_4)
----------------------------------------------------------------------
Traceback (most recent call last):
  File "/home/chenrongyi/codes/VersiBCB_Benchmark/test_1_0.py", line 69, in test_case_4
    task_func(10000, 0, 100)
    ^^^^^^^^^
NameError: name 'task_func' is not defined

======================================================================
ERROR: test_case_5 (test_1_0.TestCases.test_case_5)
----------------------------------------------------------------------
Traceback (most recent call last):
  File "/home/chenrongyi/codes/VersiBCB_Benchmark/test_1_0.py", line 74, in test_case_5
    task_func(1000, 900, 100)
    ^^^^^^^^^
NameError: name 'task_func' is not defined

======================================================================
ERROR: test_case_6 (test_1_0.TestCases.test_case_6)
----------------------------------------------------------------------
Traceback (most recent call last):
  File "/home/chenrongyi/codes/VersiBCB_Benchmark/test_1_0.py", line 79, in test_case_6
    df = task_func(0, 500, 100, columns=columns)
         ^^^^^^^^^
NameError: name 'task_func' is not defined

======================================================================
ERROR: test_case_7 (test_1_0.TestCases.test_case_7)
----------------------------------------------------------------------
Traceback (most recent call last):
  File "/home/chenrongyi/codes/VersiBCB_Benchmark/test_1_0.py", line 90, in test_case_7
    task_func(0, 500, 100, [])
    ^^^^^^^^^
NameError: name 'task_func' is not defined

======================================================================
ERROR: test_case_8 (test_1_0.TestCases.test_case_8)
----------------------------------------------------------------------
Traceback (most recent call last):
  File "/home/chenrongyi/codes/VersiBCB_Benchmark/test_1_0.py", line 97, in test_case_8
    df1 = task_func(0, 500, 100, random_seed=42)
          ^^^^^^^^^
NameError: name 'task_func' is not defined

======================================================================
ERROR: test_case_9 (test_1_0.TestCases.test_case_9)
----------------------------------------------------------------------
Traceback (most recent call last):
  File "/home/chenrongyi/codes/VersiBCB_Benchmark/test_1_0.py", line 104, in test_case_9
    task_func(0, 1000, -100)  # Step is negative
    ^^^^^^^^^
NameError: name 'task_func' is not defined

----------------------------------------------------------------------
Ran 9 tests in 0.019s

FAILED (errors=9)

stdout:

Traceback:
 Traceback (most recent call last):
  File "/home/chenrongyi/codes/VersiBCB_Benchmark/utils/testPassBCB.py", line 92, in passTaskTest
    result = run_tests_in_virtualenv(venv_dir, test_file_path,outputTestInfo=outputTestInfo)
  File "/home/chenrongyi/codes/VersiBCB_Benchmark/utils/testPassBCB.py", line 33, in run_tests_in_virtualenv
    raise subprocess.CalledProcessError(
subprocess.CalledProcessError: Command '['/datanfs2/chenrongyi/conda_env/datetime5.5_numpy2.2.1_pandas2.2.3_python3.12/bin/python', '-m', 'unittest', 'test_1_0.py']' returned non-zero exit status 1.

refcode测试失败，BigCodeBench/484的依赖{'datetime': '5.5', 'numpy': '2.2.1', 'pandas': '2.2.3', 'python': '3.12'}需要适配
错误信息:
Command '['/datanfs2/chenrongyi/conda_env/datetime5.5_numpy2.2.1_pandas2.2.3_python3.12/bin/python', '-m', 'unittest', 'test_1_0.py']' returned non-zero exit status 1.
stderr:
Traceback (most recent call last):
  File "<frozen runpy>", line 198, in _run_module_as_main
  File "<frozen runpy>", line 88, in _run_code
  File "/datanfs2/chenrongyi/conda_env/datetime5.5_numpy2.2.1_pandas2.2.3_python3.12/lib/python3.12/unittest/__main__.py", line 18, in <module>
    main(module=None)
  File "/datanfs2/chenrongyi/conda_env/datetime5.5_numpy2.2.1_pandas2.2.3_python3.12/lib/python3.12/unittest/main.py", line 104, in __init__
    self.parseArgs(argv)
  File "/datanfs2/chenrongyi/conda_env/datetime5.5_numpy2.2.1_pandas2.2.3_python3.12/lib/python3.12/unittest/main.py", line 153, in parseArgs
    self.createTests()
  File "/datanfs2/chenrongyi/conda_env/datetime5.5_numpy2.2.1_pandas2.2.3_python3.12/lib/python3.12/unittest/main.py", line 164, in createTests
    self.test = self.testLoader.loadTestsFromNames(self.testNames,
                ^^^^^^^^^^^^^^^^^^^^^^^^^^^^^^^^^^^^^^^^^^^^^^^^^^
  File "/datanfs2/chenrongyi/conda_env/datetime5.5_numpy2.2.1_pandas2.2.3_python3.12/lib/python3.12/unittest/loader.py", line 207, in loadTestsFromNames
    suites = [self.loadTestsFromName(name, module) for name in names]
              ^^^^^^^^^^^^^^^^^^^^^^^^^^^^^^^^^^^^
  File "/datanfs2/chenrongyi/conda_env/datetime5.5_numpy2.2.1_pandas2.2.3_python3.12/lib/python3.12/unittest/loader.py", line 137, in loadTestsFromName
    module = __import__(module_name)
             ^^^^^^^^^^^^^^^^^^^^^^^
  File "/home/chenrongyi/codes/VersiBCB_Benchmark/test_1_0.py", line 28
    </end>
    ^
SyntaxError: invalid syntax

stdout:

Traceback:
 Traceback (most recent call last):
  File "/home/chenrongyi/codes/VersiBCB_Benchmark/utils/testPassBCB.py", line 92, in passTaskTest
    result = run_tests_in_virtualenv(venv_dir, test_file_path,outputTestInfo=outputTestInfo)
  File "/home/chenrongyi/codes/VersiBCB_Benchmark/utils/testPassBCB.py", line 33, in run_tests_in_virtualenv
    raise subprocess.CalledProcessError(
subprocess.CalledProcessError: Command '['/datanfs2/chenrongyi/conda_env/datetime5.5_numpy2.2.1_pandas2.2.3_python3.12/bin/python', '-m', 'unittest', 'test_1_0.py']' returned non-zero exit status 1.

