refcode测试失败，BigCodeBench/491的依赖{'datetime': '5.5', 'matplotlib': '3.10.0', 'python': '3.12'}需要适配
错误信息:
Command '['/datanfs2/chenrongyi/conda_env/datetime5.5_matplotlib3.10.0_python3.12/bin/python', '-m', 'unittest', 'test_1_0.py']' returned non-zero exit status 1.
stderr:
Traceback (most recent call last):
  File "<frozen runpy>", line 198, in _run_module_as_main
  File "<frozen runpy>", line 88, in _run_code
  File "/datanfs2/chenrongyi/conda_env/datetime5.5_matplotlib3.10.0_python3.12/lib/python3.12/unittest/__main__.py", line 18, in <module>
    main(module=None)
  File "/datanfs2/chenrongyi/conda_env/datetime5.5_matplotlib3.10.0_python3.12/lib/python3.12/unittest/main.py", line 104, in __init__
    self.parseArgs(argv)
  File "/datanfs2/chenrongyi/conda_env/datetime5.5_matplotlib3.10.0_python3.12/lib/python3.12/unittest/main.py", line 153, in parseArgs
    self.createTests()
  File "/datanfs2/chenrongyi/conda_env/datetime5.5_matplotlib3.10.0_python3.12/lib/python3.12/unittest/main.py", line 164, in createTests
    self.test = self.testLoader.loadTestsFromNames(self.testNames,
                ^^^^^^^^^^^^^^^^^^^^^^^^^^^^^^^^^^^^^^^^^^^^^^^^^^
  File "/datanfs2/chenrongyi/conda_env/datetime5.5_matplotlib3.10.0_python3.12/lib/python3.12/unittest/loader.py", line 207, in loadTestsFromNames
    suites = [self.loadTestsFromName(name, module) for name in names]
              ^^^^^^^^^^^^^^^^^^^^^^^^^^^^^^^^^^^^
  File "/datanfs2/chenrongyi/conda_env/datetime5.5_matplotlib3.10.0_python3.12/lib/python3.12/unittest/loader.py", line 137, in loadTestsFromName
    module = __import__(module_name)
             ^^^^^^^^^^^^^^^^^^^^^^^
  File "/home/chenrongyi/codes/VersiBCB_Benchmark/test_1_0.py", line 18
    x = range(len(sales_data[categories[0]])
             ^
SyntaxError: '(' was never closed

stdout:

Traceback:
 Traceback (most recent call last):
  File "/home/chenrongyi/codes/VersiBCB_Benchmark/utils/testPassBCB.py", line 92, in passTaskTest
    result = run_tests_in_virtualenv(venv_dir, test_file_path,outputTestInfo=outputTestInfo)
  File "/home/chenrongyi/codes/VersiBCB_Benchmark/utils/testPassBCB.py", line 33, in run_tests_in_virtualenv
    raise subprocess.CalledProcessError(
subprocess.CalledProcessError: Command '['/datanfs2/chenrongyi/conda_env/datetime5.5_matplotlib3.10.0_python3.12/bin/python', '-m', 'unittest', 'test_1_0.py']' returned non-zero exit status 1.

refcode测试失败，BigCodeBench/491的依赖{'datetime': '5.5', 'matplotlib': '3.10.0', 'python': '3.12'}需要适配
错误信息:
Command '['/datanfs2/chenrongyi/conda_env/datetime5.5_matplotlib3.10.0_python3.12/bin/python', '-m', 'unittest', 'test_1_0.py']' returned non-zero exit status 1.
stderr:
EEEE..
======================================================================
ERROR: test_case_1 (test_1_0.TestCases.test_case_1)
----------------------------------------------------------------------
Traceback (most recent call last):
  File "/home/chenrongyi/codes/VersiBCB_Benchmark/test_1_0.py", line 49, in test_case_1
    sales_data, ax = task_func(1609459200000, seed=1)
                     ^^^^^^^^^^^^^^^^^^^^^^^^^^^^^^^^
  File "/home/chenrongyi/codes/VersiBCB_Benchmark/test_1_0.py", line 9, in task_func
    if epoch_milliseconds < 0 or epoch_milliseconds > datetime.datetime.now().timestamp() * 1000:
                                                      ^^^^^^^^^^^^^^^^^
AttributeError: type object 'datetime.datetime' has no attribute 'datetime'

======================================================================
ERROR: test_case_2 (test_1_0.TestCases.test_case_2)
----------------------------------------------------------------------
Traceback (most recent call last):
  File "/home/chenrongyi/codes/VersiBCB_Benchmark/test_1_0.py", line 62, in test_case_2
    task_func(current_epoch, seed=2)
  File "/home/chenrongyi/codes/VersiBCB_Benchmark/test_1_0.py", line 9, in task_func
    if epoch_milliseconds < 0 or epoch_milliseconds > datetime.datetime.now().timestamp() * 1000:
                                                      ^^^^^^^^^^^^^^^^^
AttributeError: type object 'datetime.datetime' has no attribute 'datetime'

======================================================================
ERROR: test_case_3 (test_1_0.TestCases.test_case_3)
----------------------------------------------------------------------
Traceback (most recent call last):
  File "/home/chenrongyi/codes/VersiBCB_Benchmark/test_1_0.py", line 67, in test_case_3
    sales_data1, _ = task_func(t, seed=42)
                     ^^^^^^^^^^^^^^^^^^^^^
  File "/home/chenrongyi/codes/VersiBCB_Benchmark/test_1_0.py", line 9, in task_func
    if epoch_milliseconds < 0 or epoch_milliseconds > datetime.datetime.now().timestamp() * 1000:
                                                      ^^^^^^^^^^^^^^^^^
AttributeError: type object 'datetime.datetime' has no attribute 'datetime'

======================================================================
ERROR: test_case_4 (test_1_0.TestCases.test_case_4)
----------------------------------------------------------------------
Traceback (most recent call last):
  File "/home/chenrongyi/codes/VersiBCB_Benchmark/test_1_0.py", line 77, in test_case_4
    task_func(future_epoch, seed=4)
  File "/home/chenrongyi/codes/VersiBCB_Benchmark/test_1_0.py", line 9, in task_func
    if epoch_milliseconds < 0 or epoch_milliseconds > datetime.datetime.now().timestamp() * 1000:
                                                      ^^^^^^^^^^^^^^^^^
AttributeError: type object 'datetime.datetime' has no attribute 'datetime'

----------------------------------------------------------------------
Ran 6 tests in 0.006s

FAILED (errors=4)

stdout:

Traceback:
 Traceback (most recent call last):
  File "/home/chenrongyi/codes/VersiBCB_Benchmark/utils/testPassBCB.py", line 92, in passTaskTest
    result = run_tests_in_virtualenv(venv_dir, test_file_path,outputTestInfo=outputTestInfo)
  File "/home/chenrongyi/codes/VersiBCB_Benchmark/utils/testPassBCB.py", line 33, in run_tests_in_virtualenv
    raise subprocess.CalledProcessError(
subprocess.CalledProcessError: Command '['/datanfs2/chenrongyi/conda_env/datetime5.5_matplotlib3.10.0_python3.12/bin/python', '-m', 'unittest', 'test_1_0.py']' returned non-zero exit status 1.

refcode测试失败，BigCodeBench/491的依赖{'datetime': '5.5', 'matplotlib': '3.10.0', 'python': '3.12'}需要适配
错误信息:
Command '['/datanfs2/chenrongyi/conda_env/datetime5.5_matplotlib3.10.0_python3.12/bin/python', '-m', 'unittest', 'test_1_0.py']' returned non-zero exit status 1.
stderr:
EEEE..
======================================================================
ERROR: test_case_1 (test_1_0.TestCases.test_case_1)
----------------------------------------------------------------------
Traceback (most recent call last):
  File "/home/chenrongyi/codes/VersiBCB_Benchmark/test_1_0.py", line 49, in test_case_1
    sales_data, ax = task_func(1609459200000, seed=1)
                     ^^^^^^^^^^^^^^^^^^^^^^^^^^^^^^^^
  File "/home/chenrongyi/codes/VersiBCB_Benchmark/test_1_0.py", line 9, in task_func
    if epoch_milliseconds < 0 or epoch_milliseconds > datetime.datetime.now().timestamp() * 1000:
                                                      ^^^^^^^^^^^^^^^^^
AttributeError: type object 'datetime.datetime' has no attribute 'datetime'

======================================================================
ERROR: test_case_2 (test_1_0.TestCases.test_case_2)
----------------------------------------------------------------------
Traceback (most recent call last):
  File "/home/chenrongyi/codes/VersiBCB_Benchmark/test_1_0.py", line 62, in test_case_2
    task_func(current_epoch, seed=2)
  File "/home/chenrongyi/codes/VersiBCB_Benchmark/test_1_0.py", line 9, in task_func
    if epoch_milliseconds < 0 or epoch_milliseconds > datetime.datetime.now().timestamp() * 1000:
                                                      ^^^^^^^^^^^^^^^^^
AttributeError: type object 'datetime.datetime' has no attribute 'datetime'

======================================================================
ERROR: test_case_3 (test_1_0.TestCases.test_case_3)
----------------------------------------------------------------------
Traceback (most recent call last):
  File "/home/chenrongyi/codes/VersiBCB_Benchmark/test_1_0.py", line 67, in test_case_3
    sales_data1, _ = task_func(t, seed=42)
                     ^^^^^^^^^^^^^^^^^^^^^
  File "/home/chenrongyi/codes/VersiBCB_Benchmark/test_1_0.py", line 9, in task_func
    if epoch_milliseconds < 0 or epoch_milliseconds > datetime.datetime.now().timestamp() * 1000:
                                                      ^^^^^^^^^^^^^^^^^
AttributeError: type object 'datetime.datetime' has no attribute 'datetime'

======================================================================
ERROR: test_case_4 (test_1_0.TestCases.test_case_4)
----------------------------------------------------------------------
Traceback (most recent call last):
  File "/home/chenrongyi/codes/VersiBCB_Benchmark/test_1_0.py", line 77, in test_case_4
    task_func(future_epoch, seed=4)
  File "/home/chenrongyi/codes/VersiBCB_Benchmark/test_1_0.py", line 9, in task_func
    if epoch_milliseconds < 0 or epoch_milliseconds > datetime.datetime.now().timestamp() * 1000:
                                                      ^^^^^^^^^^^^^^^^^
AttributeError: type object 'datetime.datetime' has no attribute 'datetime'

----------------------------------------------------------------------
Ran 6 tests in 0.005s

FAILED (errors=4)

stdout:

Traceback:
 Traceback (most recent call last):
  File "/home/chenrongyi/codes/VersiBCB_Benchmark/utils/testPassBCB.py", line 92, in passTaskTest
    result = run_tests_in_virtualenv(venv_dir, test_file_path,outputTestInfo=outputTestInfo)
  File "/home/chenrongyi/codes/VersiBCB_Benchmark/utils/testPassBCB.py", line 33, in run_tests_in_virtualenv
    raise subprocess.CalledProcessError(
subprocess.CalledProcessError: Command '['/datanfs2/chenrongyi/conda_env/datetime5.5_matplotlib3.10.0_python3.12/bin/python', '-m', 'unittest', 'test_1_0.py']' returned non-zero exit status 1.

