refcode测试失败，BigCodeBench/501的依赖{'pandas': '2.2.3', 'python': '3.12', 'xlrd': '2.0.1', 'xlwt': '1.2.0'}需要适配
错误信息:
Command '['/datanfs2/chenrongyi/conda_env/pandas2.2.3_python3.12_xlrd2.0.1_xlwt1.2.0/bin/python', '-m', 'unittest', 'test_1_0.py']' returned non-zero exit status 1.
stderr:
Traceback (most recent call last):
  File "<frozen runpy>", line 198, in _run_module_as_main
  File "<frozen runpy>", line 88, in _run_code
  File "/datanfs2/chenrongyi/conda_env/pandas2.2.3_python3.12_xlrd2.0.1_xlwt1.2.0/lib/python3.12/unittest/__main__.py", line 18, in <module>
    main(module=None)
  File "/datanfs2/chenrongyi/conda_env/pandas2.2.3_python3.12_xlrd2.0.1_xlwt1.2.0/lib/python3.12/unittest/main.py", line 104, in __init__
    self.parseArgs(argv)
  File "/datanfs2/chenrongyi/conda_env/pandas2.2.3_python3.12_xlrd2.0.1_xlwt1.2.0/lib/python3.12/unittest/main.py", line 153, in parseArgs
    self.createTests()
  File "/datanfs2/chenrongyi/conda_env/pandas2.2.3_python3.12_xlrd2.0.1_xlwt1.2.0/lib/python3.12/unittest/main.py", line 164, in createTests
    self.test = self.testLoader.loadTestsFromNames(self.testNames,
                ^^^^^^^^^^^^^^^^^^^^^^^^^^^^^^^^^^^^^^^^^^^^^^^^^^
  File "/datanfs2/chenrongyi/conda_env/pandas2.2.3_python3.12_xlrd2.0.1_xlwt1.2.0/lib/python3.12/unittest/loader.py", line 207, in loadTestsFromNames
    suites = [self.loadTestsFromName(name, module) for name in names]
              ^^^^^^^^^^^^^^^^^^^^^^^^^^^^^^^^^^^^
  File "/datanfs2/chenrongyi/conda_env/pandas2.2.3_python3.12_xlrd2.0.1_xlwt1.2.0/lib/python3.12/unittest/loader.py", line 137, in loadTestsFromName
    module = __import__(module_name)
             ^^^^^^^^^^^^^^^^^^^^^^^
  File "/home/chenrongyi/codes/VersiBCB_Benchmark/test_1_0.py", line 41
    </end>
    ^
SyntaxError: invalid syntax

stdout:

Traceback:
 Traceback (most recent call last):
  File "/home/chenrongyi/codes/VersiBCB_Benchmark/utils/testPassBCB.py", line 92, in passTaskTest
    result = run_tests_in_virtualenv(venv_dir, test_file_path,outputTestInfo=outputTestInfo)
  File "/home/chenrongyi/codes/VersiBCB_Benchmark/utils/testPassBCB.py", line 33, in run_tests_in_virtualenv
    raise subprocess.CalledProcessError(
subprocess.CalledProcessError: Command '['/datanfs2/chenrongyi/conda_env/pandas2.2.3_python3.12_xlrd2.0.1_xlwt1.2.0/bin/python', '-m', 'unittest', 'test_1_0.py']' returned non-zero exit status 1.

refcode测试失败，BigCodeBench/501的依赖{'pandas': '2.2.3', 'python': '3.12', 'xlrd': '2.0.1', 'xlwt': '1.2.0'}需要适配
错误信息:
Command '['/datanfs2/chenrongyi/conda_env/pandas2.2.3_python3.12_xlrd2.0.1_xlwt1.2.0/bin/python', '-m', 'unittest', 'test_1_0.py']' returned non-zero exit status 1.
stderr:
Traceback (most recent call last):
  File "<frozen runpy>", line 198, in _run_module_as_main
  File "<frozen runpy>", line 88, in _run_code
  File "/datanfs2/chenrongyi/conda_env/pandas2.2.3_python3.12_xlrd2.0.1_xlwt1.2.0/lib/python3.12/unittest/__main__.py", line 18, in <module>
    main(module=None)
  File "/datanfs2/chenrongyi/conda_env/pandas2.2.3_python3.12_xlrd2.0.1_xlwt1.2.0/lib/python3.12/unittest/main.py", line 104, in __init__
    self.parseArgs(argv)
  File "/datanfs2/chenrongyi/conda_env/pandas2.2.3_python3.12_xlrd2.0.1_xlwt1.2.0/lib/python3.12/unittest/main.py", line 153, in parseArgs
    self.createTests()
  File "/datanfs2/chenrongyi/conda_env/pandas2.2.3_python3.12_xlrd2.0.1_xlwt1.2.0/lib/python3.12/unittest/main.py", line 164, in createTests
    self.test = self.testLoader.loadTestsFromNames(self.testNames,
                ^^^^^^^^^^^^^^^^^^^^^^^^^^^^^^^^^^^^^^^^^^^^^^^^^^
  File "/datanfs2/chenrongyi/conda_env/pandas2.2.3_python3.12_xlrd2.0.1_xlwt1.2.0/lib/python3.12/unittest/loader.py", line 207, in loadTestsFromNames
    suites = [self.loadTestsFromName(name, module) for name in names]
              ^^^^^^^^^^^^^^^^^^^^^^^^^^^^^^^^^^^^
  File "/datanfs2/chenrongyi/conda_env/pandas2.2.3_python3.12_xlrd2.0.1_xlwt1.2.0/lib/python3.12/unittest/loader.py", line 137, in loadTestsFromName
    module = __import__(module_name)
             ^^^^^^^^^^^^^^^^^^^^^^^
  File "/home/chenrongyi/codes/VersiBCB_Benchmark/test_1_0.py", line 35
    </end>
    ^
SyntaxError: invalid syntax

stdout:

Traceback:
 Traceback (most recent call last):
  File "/home/chenrongyi/codes/VersiBCB_Benchmark/utils/testPassBCB.py", line 92, in passTaskTest
    result = run_tests_in_virtualenv(venv_dir, test_file_path,outputTestInfo=outputTestInfo)
  File "/home/chenrongyi/codes/VersiBCB_Benchmark/utils/testPassBCB.py", line 33, in run_tests_in_virtualenv
    raise subprocess.CalledProcessError(
subprocess.CalledProcessError: Command '['/datanfs2/chenrongyi/conda_env/pandas2.2.3_python3.12_xlrd2.0.1_xlwt1.2.0/bin/python', '-m', 'unittest', 'test_1_0.py']' returned non-zero exit status 1.

refcode测试失败，BigCodeBench/501的依赖{'pandas': '2.2.3', 'python': '3.12', 'xlrd': '2.0.1', 'xlwt': '1.2.0'}需要适配
错误信息:
Command '['/datanfs2/chenrongyi/conda_env/pandas2.2.3_python3.12_xlrd2.0.1_xlwt1.2.0/bin/python', '-m', 'unittest', 'test_1_0.py']' returned non-zero exit status 1.
stderr:
EEE..E
======================================================================
ERROR: test_custom_sheet_name (test_1_0.TestCases.test_custom_sheet_name)
----------------------------------------------------------------------
Traceback (most recent call last):
  File "/datanfs2/chenrongyi/conda_env/pandas2.2.3_python3.12_xlrd2.0.1_xlwt1.2.0/lib/python3.12/site-packages/pandas/io/excel/_util.py", line 93, in get_writer
    return _writers[engine_name]
           ~~~~~~~~^^^^^^^^^^^^^
KeyError: 'xlwt'

The above exception was the direct cause of the following exception:

Traceback (most recent call last):
  File "/home/chenrongyi/codes/VersiBCB_Benchmark/test_1_0.py", line 55, in test_custom_sheet_name
    file_path = task_func(json_str, 'test_custom_sheet.xls', sheet_name="Data")
                ^^^^^^^^^^^^^^^^^^^^^^^^^^^^^^^^^^^^^^^^^^^^^^^^^^^^^^^^^^^^^^^
  File "/home/chenrongyi/codes/VersiBCB_Benchmark/test_1_0.py", line 18, in task_func
    writer = pd.ExcelWriter(filename, engine='xlwt')
             ^^^^^^^^^^^^^^^^^^^^^^^^^^^^^^^^^^^^^^^
  File "/datanfs2/chenrongyi/conda_env/pandas2.2.3_python3.12_xlrd2.0.1_xlwt1.2.0/lib/python3.12/site-packages/pandas/io/excel/_base.py", line 1146, in __new__
    cls = get_writer(engine)  # type: ignore[assignment]
          ^^^^^^^^^^^^^^^^^^
  File "/datanfs2/chenrongyi/conda_env/pandas2.2.3_python3.12_xlrd2.0.1_xlwt1.2.0/lib/python3.12/site-packages/pandas/io/excel/_util.py", line 95, in get_writer
    raise ValueError(f"No Excel writer '{engine_name}'") from err
ValueError: No Excel writer 'xlwt'

======================================================================
ERROR: test_empty_json (test_1_0.TestCases.test_empty_json)
----------------------------------------------------------------------
Traceback (most recent call last):
  File "/datanfs2/chenrongyi/conda_env/pandas2.2.3_python3.12_xlrd2.0.1_xlwt1.2.0/lib/python3.12/site-packages/pandas/io/excel/_util.py", line 93, in get_writer
    return _writers[engine_name]
           ~~~~~~~~^^^^^^^^^^^^^
KeyError: 'xlwt'

The above exception was the direct cause of the following exception:

Traceback (most recent call last):
  File "/home/chenrongyi/codes/VersiBCB_Benchmark/test_1_0.py", line 41, in test_empty_json
    file_path = task_func('[]', 'test_empty.xls')
                ^^^^^^^^^^^^^^^^^^^^^^^^^^^^^^^^^
  File "/home/chenrongyi/codes/VersiBCB_Benchmark/test_1_0.py", line 18, in task_func
    writer = pd.ExcelWriter(filename, engine='xlwt')
             ^^^^^^^^^^^^^^^^^^^^^^^^^^^^^^^^^^^^^^^
  File "/datanfs2/chenrongyi/conda_env/pandas2.2.3_python3.12_xlrd2.0.1_xlwt1.2.0/lib/python3.12/site-packages/pandas/io/excel/_base.py", line 1146, in __new__
    cls = get_writer(engine)  # type: ignore[assignment]
          ^^^^^^^^^^^^^^^^^^
  File "/datanfs2/chenrongyi/conda_env/pandas2.2.3_python3.12_xlrd2.0.1_xlwt1.2.0/lib/python3.12/site-packages/pandas/io/excel/_util.py", line 95, in get_writer
    raise ValueError(f"No Excel writer '{engine_name}'") from err
ValueError: No Excel writer 'xlwt'

======================================================================
ERROR: test_file_content (test_1_0.TestCases.test_file_content)
----------------------------------------------------------------------
Traceback (most recent call last):
  File "/datanfs2/chenrongyi/conda_env/pandas2.2.3_python3.12_xlrd2.0.1_xlwt1.2.0/lib/python3.12/site-packages/pandas/io/excel/_util.py", line 93, in get_writer
    return _writers[engine_name]
           ~~~~~~~~^^^^^^^^^^^^^
KeyError: 'xlwt'

The above exception was the direct cause of the following exception:

Traceback (most recent call last):
  File "/home/chenrongyi/codes/VersiBCB_Benchmark/test_1_0.py", line 61, in test_file_content
    file_path = task_func(json_str, 'test_content.xls')
                ^^^^^^^^^^^^^^^^^^^^^^^^^^^^^^^^^^^^^^^
  File "/home/chenrongyi/codes/VersiBCB_Benchmark/test_1_0.py", line 18, in task_func
    writer = pd.ExcelWriter(filename, engine='xlwt')
             ^^^^^^^^^^^^^^^^^^^^^^^^^^^^^^^^^^^^^^^
  File "/datanfs2/chenrongyi/conda_env/pandas2.2.3_python3.12_xlrd2.0.1_xlwt1.2.0/lib/python3.12/site-packages/pandas/io/excel/_base.py", line 1146, in __new__
    cls = get_writer(engine)  # type: ignore[assignment]
          ^^^^^^^^^^^^^^^^^^
  File "/datanfs2/chenrongyi/conda_env/pandas2.2.3_python3.12_xlrd2.0.1_xlwt1.2.0/lib/python3.12/site-packages/pandas/io/excel/_util.py", line 95, in get_writer
    raise ValueError(f"No Excel writer '{engine_name}'") from err
ValueError: No Excel writer 'xlwt'

======================================================================
ERROR: test_valid_json (test_1_0.TestCases.test_valid_json)
----------------------------------------------------------------------
Traceback (most recent call last):
  File "/datanfs2/chenrongyi/conda_env/pandas2.2.3_python3.12_xlrd2.0.1_xlwt1.2.0/lib/python3.12/site-packages/pandas/io/excel/_util.py", line 93, in get_writer
    return _writers[engine_name]
           ~~~~~~~~^^^^^^^^^^^^^
KeyError: 'xlwt'

The above exception was the direct cause of the following exception:

Traceback (most recent call last):
  File "/home/chenrongyi/codes/VersiBCB_Benchmark/test_1_0.py", line 32, in test_valid_json
    file_path = task_func(json_str, 'test_valid.xls')
                ^^^^^^^^^^^^^^^^^^^^^^^^^^^^^^^^^^^^^
  File "/home/chenrongyi/codes/VersiBCB_Benchmark/test_1_0.py", line 18, in task_func
    writer = pd.ExcelWriter(filename, engine='xlwt')
             ^^^^^^^^^^^^^^^^^^^^^^^^^^^^^^^^^^^^^^^
  File "/datanfs2/chenrongyi/conda_env/pandas2.2.3_python3.12_xlrd2.0.1_xlwt1.2.0/lib/python3.12/site-packages/pandas/io/excel/_base.py", line 1146, in __new__
    cls = get_writer(engine)  # type: ignore[assignment]
          ^^^^^^^^^^^^^^^^^^
  File "/datanfs2/chenrongyi/conda_env/pandas2.2.3_python3.12_xlrd2.0.1_xlwt1.2.0/lib/python3.12/site-packages/pandas/io/excel/_util.py", line 95, in get_writer
    raise ValueError(f"No Excel writer '{engine_name}'") from err
ValueError: No Excel writer 'xlwt'

----------------------------------------------------------------------
Ran 6 tests in 0.007s

FAILED (errors=4)

stdout:

Traceback:
 Traceback (most recent call last):
  File "/home/chenrongyi/codes/VersiBCB_Benchmark/utils/testPassBCB.py", line 92, in passTaskTest
    result = run_tests_in_virtualenv(venv_dir, test_file_path,outputTestInfo=outputTestInfo)
  File "/home/chenrongyi/codes/VersiBCB_Benchmark/utils/testPassBCB.py", line 33, in run_tests_in_virtualenv
    raise subprocess.CalledProcessError(
subprocess.CalledProcessError: Command '['/datanfs2/chenrongyi/conda_env/pandas2.2.3_python3.12_xlrd2.0.1_xlwt1.2.0/bin/python', '-m', 'unittest', 'test_1_0.py']' returned non-zero exit status 1.

